Workbook

Sheet EDT
A1: EDT del Momento 2 — Patient Progress Auditor
A2: Horas y días son una propuesta de Claude: una persona con ayuda de IA, incluye revisar y probar, ninguna tarea pasa de 4 h. Se congela el jueves 29 (tag m2-entrega); el viernes no se integra nada nuevo.
B3: TOTAL de la EDT (sin tareas recortadas) | K3: =K7+K15+K30+K35+K41+K51+K55+K62+K76+K87+K93+K97+K104+K112+K122 -> 185 | L3: =L7+L15+L30+L35+L41+L51+L55+L62+L76+L87+L93+L97+L104+L112+L122 -> 0 | N3: =IFERROR((K7*N7+K15*N15+K30*N30+K35*N35+K41*N41+K51*N51+K55*N55+K62*N62+K76*N76+K87*N87+K93*N93+K97*N97+K104*N104+K112*N112+K122*N122)/K3,0) -> 0
B4: Leyenda · Amarillo = lo llena el equipo (Responsable, Horas reales, Estado, Notas) | C4: Texto azul = propuesta de Claude que se puede cambiar (Frente, Hito, Prioridad, Día, Horas est.) | D4: Estado «Recortada» = la tarea sale de todos los totales y del Cronograma
A6: ID | B6: Tarea | C6: Entregable | D6: Frente | E6: Responsable | F6: Requisitos | G6: Hito | H6: Prioridad | I6: Depende de | J6: Día | K6: Horas est. | L6: Horas reales | M6: Estado | N6: Avance | O6: Criterio de aceptación (sí/no) | P6: Notas
A7: 1 | B7: Arranque en frío y plataforma | C7: La app levanta con un comando en una máquina limpia, sin pasos manuales: es la puerta de aceptación del profesor | D7: A · Plataforma y datos | K7: =SUMIFS(K8:K14,M8:M14,"<>Recortada") -> 9.5 | L7: =SUM(L8:L14) -> 0 | M7: =IF(COUNTIF(M8:M14,"Recortada")=COUNTA(M8:M14),"Recortada",IF(COUNTIF(M8:M14,"Hecha")+COUNTIF(M8:M14,"Recortada")=COUNTA(M8:M14),"Hecha",IF(COUNTIF(M8:M14,"Bloqueada")>0,"Bloqueada",IF(COUNTIF(M8:M14,"En curso")+COUNTIF(M8:M14,"Hecha")>0,"En curso","Pendiente")))) -> Pendiente | N7: =IFERROR(SUMPRODUCT((M8:M14<>"Recortada")*K8:K14*N8:N14)/K7,0) -> 0
A8: 1.1 | B8: Quitar la exigencia de JWT_SECRET en el Momento 2 | C8: application.yml, .env.example y la cadena de seguridad sin token: el backend arranca sin JWT_SECRET y las rutas /api no piden token | D8: A · Plataforma y datos | F8: D23, D26, RNF-13 | G8: M2-N | H8: 1 · Imprescindible | I8: — | J8: Mié 28 | K8: 1 | M8: Pendiente | N8: =IF(M8="Hecha",1,IF(M8="En curso",0.5,0)) -> 0 | O8: ¿El backend arranca sin JWT_SECRET y responde en /api sin token?
A9: 1.2 | B9: Dockerfile del backend con CMD | C9: Imagen multi-etapa con Java 17 que compila y arranca el jar | D9: A · Plataforma y datos | F9: D9, D22 | G9: M2-N | H9: 1 · Imprescindible | I9: 1.1 | J9: Mié 28 | K9: 1 | M9: Pendiente | N9: =IF(M9="Hecha",1,IF(M9="En curso",0.5,0)) -> 0 | O9: ¿La imagen del backend arranca sola con docker run?
A10: 1.3 | B10: Dockerfile del frontend multi-etapa | C10: Build de Angular con Node 20 servido con nginx; la URL del API es configurable | D10: A · Plataforma y datos | F10: D22 | G10: M2-N | H10: 1 · Imprescindible | I10: — | J10: Mié 28 | K10: 1.5 | M10: Pendiente | N10: =IF(M10="Hecha",1,IF(M10="En curso",0.5,0)) -> 0 | O10: ¿La imagen sirve la app y esta llama al backend?
A11: 1.4 | B11: docker-compose.yml | C11: PostgreSQL con imagen y versión fijadas, backend y frontend, con healthchecks y orden de arranque | D11: A · Plataforma y datos | F11: D22, RNF-13 | G11: M2-N | H11: 1 · Imprescindible | I11: 1.2, 1.3 | J11: Mié 28 | K11: 2 | M11: Pendiente | N11: =IF(M11="Hecha",1,IF(M11="En curso",0.5,0)) -> 0 | O11: ¿docker compose up --build deja los tres servicios sanos?
A12: 1.5 | B12: .env.example | C12: Variables exactas (DB_PASSWORD, llave del proveedor y del respaldo, APP_SEED_DEMO, API_URL), sin llaves reales | D12: A · Plataforma y datos | F12: D22, RNF-01, RNF-13 | G12: M2-N | H12: 1 · Imprescindible | I12: — | J12: Mié 28 | K12: 0.5 | M12: Pendiente | N12: =IF(M12="Hecha",1,IF(M12="En curso",0.5,0)) -> 0 | O12: ¿Toda variable que usa el código está documentada y ninguna es una llave real?
A13: 1.6 | B13: run.sh | C13: Verifica Docker, crea .env, genera DB_PASSWORD, resuelve la llave (entorno; consola solo si hay terminal; si no, arranca y avisa) y ejecuta docker compose up --build | D13: A · Plataforma y datos | F13: D22, RNF-13 | G13: M2-N | H13: 1 · Imprescindible | I13: 1.4, 1.5 | J13: Mié 28 | K13: 2 | M13: Pendiente | N13: =IF(M13="Hecha",1,IF(M13="En curso",0.5,0)) -> 0 | O13: ¿Sin terminal y sin llave arranca igual en vez de quedarse esperando?
A14: 1.7 | B14: Aviso de llave faltante en la app | C14: Estado del proveedor en el backend y banner claro en la interfaz cuando falta la llave | D14: AB · Compartida | F14: D22, RNF-04 | G14: M2-N | H14: 1 · Imprescindible | I14: 7.2 | J14: Jue 29 | K14: 1.5 | M14: Pendiente | N14: =IF(M14="Hecha",1,IF(M14="En curso",0.5,0)) -> 0 | O14: ¿Sin llave la app avisa con claridad y no muestra un error crudo?
A15: 2 | B15: Modelo de datos, roles y semilla | C15: Esquema Flyway V3 y V4 según DICCIONARIO_DATOS_M2, entidades y datos de demostración (D11) | D15: A · Plataforma y datos | K15: =SUMIFS(K16:K29,M16:M29,"<>Recortada") -> 22 | L15: =SUM(L16:L29) -> 0 | M15: =IF(COUNTIF(M16:M29,"Recortada")=COUNTA(M16:M29),"Recortada",IF(COUNTIF(M16:M29,"Hecha")+COUNTIF(M16:M29,"Recortada")=COUNTA(M16:M29),"Hecha",IF(COUNTIF(M16:M29,"Bloqueada")>0,"Bloqueada",IF(COUNTIF(M16:M29,"En curso")+COUNTIF(M16:M29,"Hecha")>0,"En curso","Pendiente")))) -> Pendiente | N15: =IFERROR(SUMPRODUCT((M16:M29<>"Recortada")*K16:K29*N16:N29)/K15,0) -> 0
A16: 2.1 | B16: V3: tablas de usuarios y entradas | C16: app_users ajustada y patients, entries y entry_events, con sus CHECK e índices (DICCIONARIO_DATOS_M2 §4.1 a §4.5) | D16: A · Plataforma y datos | F16: RF-01, RF-02, RF-06 | G16: M2-N | H16: 1 · Imprescindible | I16: — | J16: Mié 28 | K16: 1.5 | M16: Pendiente | N16: =IF(M16="Hecha",1,IF(M16="En curso",0.5,0)) -> 0 | O16: ¿Flyway crea las tablas y el CHECK rechaza un síntoma fuera del catálogo?
A17: 2.2 | B17: V3: tablas de informes | C17: reports, report_versions, report_citations y monthly_report_weeks (§4.7 a §4.10) | D17: A · Plataforma y datos | F17: RF-08, RF-25, RF-36 | G17: M2-N | H17: 1 · Imprescindible | I17: 2.1 | J17: Mié 28 | K17: 1.5 | M17: Pendiente | N17: =IF(M17="Hecha",1,IF(M17="En curso",0.5,0)) -> 0 | O17: ¿Un informe que no empieza en lunes es rechazado por la BD?
A18: 2.3 | B18: V3: tablas del agente | C18: agent_runs y agent_steps (§4.11 y §4.12) | D18: A · Plataforma y datos | F18: RF-22, D24 | G18: M2-N | H18: 1 · Imprescindible | I18: 2.1 | J18: Mié 28 | K18: 1 | M18: Pendiente | N18: =IF(M18="Hecha",1,IF(M18="En curso",0.5,0)) -> 0 | O18: ¿Una ejecución guarda sus pasos ordenados por seq?
A19: 2.4 | B19: V3: tablas de «si hay tiempo» | C19: entry_versions y audit_logs (§4.6 y §4.13) | D19: A · Plataforma y datos | F19: RF-03, RF-35 | G19: M2-S | H19: 3 · Si hay tiempo | I19: 2.1 | J19: Jue 29 | K19: 1 | M19: Pendiente | N19: =IF(M19="Hecha",1,IF(M19="En curso",0.5,0)) -> 0 | O19: ¿Las dos tablas existen y se pueden escribir?
A20: 2.5 | B20: V4: roles y permisos del dominio | C20: ENFERMERIA, MEDICO y AGENTE y los permisos de §3.4 con sus asignaciones; UUID fijos y ON CONFLICT DO NOTHING | D20: A · Plataforma y datos | F20: RF-32, RN-02 | G20: M2-N | H20: 1 · Imprescindible | I20: 2.1 | J20: Mié 28 | K20: 1.5 | M20: Pendiente | N20: =IF(M20="Hecha",1,IF(M20="En curso",0.5,0)) -> 0 | O20: ¿Solo ENFERMERIA tiene REPORTS_APPROVE?
A21: 2.6 | B21: Entidades y repositorios | C21: Clases JPA y repositorios de las tablas del núcleo | D21: A · Plataforma y datos | F21: DICCIONARIO_DATOS_M2 §4 | G21: M2-N | H21: 1 · Imprescindible | I21: 2.1, 2.2, 2.3 | J21: Mié 28 | K21: 2 | M21: Pendiente | N21: =IF(M21="Hecha",1,IF(M21="En curso",0.5,0)) -> 0 | O21: ¿Los repositorios leen y escriben las tablas del núcleo en una prueba?
A22: 2.7 | B22: Semilla: usuarios de demostración | C22: ApplicationRunner idempotente con 4 usuarios (2 de enfermería y 2 médicos); solo con APP_SEED_DEMO=true y nunca en prod | D22: A · Plataforma y datos | F22: RF-05, RF-39, D23 | G22: M2-N | H22: 1 · Imprescindible | I22: 2.5, 2.6 | J22: Mié 28 | K22: 2 | M22: Pendiente | N22: =IF(M22="Hecha",1,IF(M22="En curso",0.5,0)) -> 0 | O22: ¿Reiniciar dos veces no duplica y el perfil prod rechaza la semilla?
A23: 2.8 | B23: Datos del paciente 1 | C23: 5 semanas (unas 35 entradas con eventos confirmados); un síntoma que reaparece en las semanas 1, 3 y 5 | D23: A · Plataforma y datos | F23: D11, OBJ-02 | G23: M2-N | H23: 1 · Imprescindible | I23: 2.7 | J23: Mié 28 | K23: 2.5 | M23: Pendiente | N23: =IF(M23="Hecha",1,IF(M23="En curso",0.5,0)) -> 0 | O23: ¿Existen las 5 semanas y el síntoma reaparece donde dice D11?
A24: 2.9 | B24: Datos del paciente 2 | C24: 4 semanas; la semana 4 queda sin informe | D24: A · Plataforma y datos | F24: D11 | G24: M2-N | H24: 2 · Núcleo | I24: 2.7 | J24: Jue 29 | K24: 2 | M24: Pendiente | N24: =IF(M24="Hecha",1,IF(M24="En curso",0.5,0)) -> 0 | O24: ¿Existen las 4 semanas con sus eventos confirmados?
A25: 2.10 | B25: Datos del paciente 3 | C25: 3 semanas con días sin registro y una semana con pocas entradas | D25: A · Plataforma y datos | F25: D11, RN-08 | G25: M2-N | H25: 2 · Núcleo | I25: 2.7 | J25: Jue 29 | K25: 1.5 | M25: Pendiente | N25: =IF(M25="Hecha",1,IF(M25="En curso",0.5,0)) -> 0 | O25: ¿El paciente tiene días sin registro y una semana con pocas entradas?
A26: 2.11 | B26: Datos del paciente 4 | C26: 4 semanas sin síntomas y con negaciones («sin vómito») | D26: A · Plataforma y datos | F26: D11, RN-11 | G26: M2-N | H26: 2 · Núcleo | I26: 2.7 | J26: Jue 29 | K26: 1.5 | M26: Pendiente | N26: =IF(M26="Hecha",1,IF(M26="En curso",0.5,0)) -> 0 | O26: ¿Las negaciones están en el texto y no generan eventos?
A27: 2.12 | B27: Datos del paciente 5 | C27: 2 semanas con una nota que trae una instrucción dentro del texto | D27: A · Plataforma y datos | F27: D11, RF-21 | G27: M2-N | H27: 2 · Núcleo | I27: 2.7 | J27: Jue 29 | K27: 1 | M27: Pendiente | N27: =IF(M27="Hecha",1,IF(M27="En curso",0.5,0)) -> 0 | O27: ¿Existe la nota con la instrucción y es texto sintético?
... A29: 2.14 | B29: Prueba de idempotencia de la semilla | C29: Reiniciar dos veces y comparar los conteos por tabla | D29: A · Plataforma y datos | F29: RF-05 | G29: M2-N | H29: 1 · Imprescindible | I29: 2.8 | J29: Jue 29 | K29: 0.5 | M29: Pendiente | N29: =IF(M29="Hecha",1,IF(M29="En curso",0.5,0)) -> 0 | O29: ¿Los conteos por tabla son iguales tras reiniciar?
A30: 3 | B30: Sesión de demostración y permisos (D26) | C30: Elegir un usuario de demostración y que el servidor aplique su rol, sin autenticación | D30: A · Plataforma y datos | K30: =SUMIFS(K31:K34,M31:M34,"<>Recortada") -> 7.5 | L30: =SUM(L31:L34) -> 0 | M30: =IF(COUNTIF(M31:M34,"Recortada")=COUNTA(M31:M34),"Recortada",IF(COUNTIF(M31:M34,"Hecha")+COUNTIF(M31:M34,"Recortada")=COUNTA(M31:M34),"Hecha",IF(COUNTIF(M31:M34,"Bloqueada")>0,"Bloqueada",IF(COUNTIF(M31:M34,"En curso")+COUNTIF(M31:M34,"Hecha")>0,"En curso","Pendiente")))) -> Pendiente | N30: =IFERROR(SUMPRODUCT((M31:M34<>"Recortada")*K31:K34*N31:N34)/K30,0) -> 0
A31: 3.1 | B31: API de usuarios de demostración y sesión | C31: Lista los usuarios sembrados; el elegido viaja en cada petición y el servidor toma de él rol e identidad | D31: A · Plataforma y datos | F31: D26, RF-32 | G31: M2-N | H31: 1 · Imprescindible | I31: 2.7 | J31: Mié 28 | K31: 2 | M31: Pendiente | N31: =IF(M31="Hecha",1,IF(M31="En curso",0.5,0)) -> 0 | O31: ¿Una petición sin usuario elegido se rechaza y con uno toma su rol?
A32: 3.2 | B32: Permisos por rol en el servidor | C32: La matriz de DICCIONARIO_DATOS_M2 §3.4 aplicada en los endpoints | D32: A · Plataforma y datos | F32: RF-32, RN-02 | G32: M2-N | H32: 1 · Imprescindible | I32: 3.1 | J32: Mié 28 | K32: 2 | M32: Pendiente | N32: =IF(M32="Hecha",1,IF(M32="En curso",0.5,0)) -> 0 | O32: ¿Cada rol hace exactamente lo que dice la matriz y nada más?
A33: 3.3 | B33: Pruebas automáticas de permisos | C33: El médico no aprueba ni ve informes pendientes; solo enfermería aprueba | D33: A · Plataforma y datos | F33: OBJ-05, RNF-11 | G33: M2-N | H33: 1 · Imprescindible | I33: 3.2, 9.4 | J33: Jue 29 | K33: 1.5 | M33: Pendiente | N33: =IF(M33="Hecha",1,IF(M33="En curso",0.5,0)) -> 0 | O33: ¿Pasan las tres pruebas: médico no aprueba, médico no ve pendientes, enfermería sí aprueba?
A34: 3.4 | B34: Pantalla de elección de usuario y guards por rol | C34: Elegir entre los usuarios sembrados, enviar el usuario en cada petición y limitar las rutas por rol | D34: A · Plataforma y datos | F34: D26 | G34: M2-N | H34: 1 · Imprescindible | I34: 3.1 | J34: Mié 28 | K34: 2 | M34: Pendiente | N34: =IF(M34="Hecha",1,IF(M34="En curso",0.5,0)) -> 0 | O34: ¿Se puede entrar como enfermería y como médico y cada uno ve solo sus rutas?
A35: 4 | B35: Pacientes y entradas | C35: Alta de pacientes, registro de entradas y consulta por fecha | D35: A · Plataforma y datos | K35: =SUMIFS(K36:K40,M36:M40,"<>Recortada") -> 8 | L35: =SUM(L36:L40) -> 0 | M35: =IF(COUNTIF(M36:M40,"Recortada")=COUNTA(M36:M40),"Recortada",IF(COUNTIF(M36:M40,"Hecha")+COUNTIF(M36:M40,"Recortada")=COUNTA(M36:M40),"Hecha",IF(COUNTIF(M36:M40,"Bloqueada")>0,"Bloqueada",IF(COUNTIF(M36:M40,"En curso")+COUNTIF(M36:M40,"Hecha")>0,"En curso","Pendiente")))) -> Pendiente | N35: =IFERROR(SUMPRODUCT((M36:M40<>"Recortada")*K36:K40*N36:N40)/K35,0) -> 0
A36: 4.1 | B36: API de pacientes | C36: Crear y listar; al LLM solo sale el id interno | D36: A · Plataforma y datos | F36: RF-01, RNF-02 | G36: M2-N | H36: 1 · Imprescindible | I36: 2.6 | J36: Mié 28 | K36: 1 | M36: Pendiente | N36: =IF(M36="Hecha",1,IF(M36="En curso",0.5,0)) -> 0 | O36: ¿Se crea un paciente con id interno y alias?
A37: 4.2 | B37: API de entradas | C37: Crear con el texto tal como se escribió, fecha y autor; listar por paciente y rango; varias el mismo día, ordenadas por hora | D37: A · Plataforma y datos | F37: RF-02, RF-04, RN-07, RN-09 | G37: M2-N | H37: 1 · Imprescindible | I37: 2.6 | J37: Mié 28 | K37: 2 | M37: Pendiente | N37: =IF(M37="Hecha",1,IF(M37="En curso",0.5,0)) -> 0 | O37: ¿El texto guardado es idéntico al enviado y el listado respeta el rango?
A38: 4.3 | B38: Pantalla: lista de pacientes y alta mínima | C38: Lista de pacientes y formulario de alta | D38: A · Plataforma y datos | F38: RF-01 | G38: M2-N | H38: 2 · Núcleo | I38: 3.4, 4.1 | J38: Mié 28 | K38: 1.5 | M38: Pendiente | N38: =IF(M38="Hecha",1,IF(M38="En curso",0.5,0)) -> 0 | O38: ¿Se ve la lista y se crea un paciente desde la pantalla?
A39: 4.4 | B39: Pantalla: historial del paciente | C39: Entradas por fecha con filtro de rango | D39: A · Plataforma y datos | F39: RF-04 | G39: M2-N | H39: 2 · Núcleo | I39: 4.2, 4.3 | J39: Mié 28 | K39: 2 | M39: Pendiente | N39: =IF(M39="Hecha",1,IF(M39="En curso",0.5,0)) -> 0 | O39: ¿El historial filtra por rango y ordena por fecha?
A40: 4.5 | B40: Pantalla de registro | C40: Texto y fecha; al enviar pide la propuesta de eventos (paquete 5) | D40: A · Plataforma y datos | F40: RF-02 | G40: M2-N | H40: 1 · Imprescindible | I40: 4.2, 3.4 | J40: Mié 28 | K40: 1.5 | M40: Pendiente | N40: =IF(M40="Hecha",1,IF(M40="En curso",0.5,0)) -> 0 | O40: ¿Se registra una entrada desde la pantalla?
A41: 5 | B41: Estructuración por IA al registrar (D27) | C41: La IA propone los eventos del texto y la persona los confirma antes de guardar | D41: B · Agente e informe | K41: =SUMIFS(K42:K50,M42:M50,"<>Recortada") -> 18.5 | L41: =SUM(L42:L50) -> 0 | M41: =IF(COUNTIF(M42:M50,"Recortada")=COUNTA(M42:M50),"Recortada",IF(COUNTIF(M42:M50,"Hecha")+COUNTIF(M42:M50,"Recortada")=COUNTA(M42:M50),"Hecha",IF(COUNTIF(M42:M50,"Bloqueada")>0,"Bloqueada",IF(COUNTIF(M42:M50,"En curso")+COUNTIF(M42:M50,"Hecha")>0,"En curso","Pendiente")))) -> Pendiente | N41: =IFERROR(SUMPRODUCT((M42:M50<>"Recortada")*K42:K50*N42:N50)/K41,0) -> 0
A42: 5.1 | B42: Esquema y prompt de la propuesta | C42: JSON con síntomas del catálogo de nueve, intensidad y veces; no agrega lo que el texto no dice y las negaciones no crean eventos | D42: B · Agente e informe | F42: RF-06, RN-11, D27 | G42: M2-N | H42: 2 · Núcleo | I42: 7.2 | J42: Mié 28 | K42: 2 | M42: Pendiente | N42: =IF(M42="Hecha",1,IF(M42="En curso",0.5,0)) -> 0 | O42: ¿«Sin vómito» no crea el evento Vómito?
...

Sheet Cronograma por día
A1: Cronograma por día — miércoles 28 a sábado 31
A2: Todo sale de la hoja EDT (columnas Día, Horas est., Responsable, Frente y Estado). Cambie el día de una tarea o márquela «Recortada» y esta hoja se recalcula sola.
A3: Personas en el equipo | C3: 2 | D3: ← suposición: el equipo son dos personas
A5: 1 · Carga por día
A6: Día | B6: Qué toca | C6: Capacidad por persona (h) | D6: Capacidad del equipo (h) | E6: Horas planeadas | F6: Carga | G6: Estado | H6: =Listas!A2 -> Breiner | I6: =Listas!A3 -> Andres | J6: Sin asignar | K6: =Listas!B2 -> A · Plataforma y datos | L6: =Listas!B3 -> B · Agente e informe | M6: =Listas!B4 -> AB · Compartida
A7: =Listas!F2 -> Mié 28 | B7: Arranque en frío, datos y semilla, registro con IA, métricas, proveedor y agente. | C7: 10 | D7: =C7*$C$3 -> 20 | E7: =SUMIFS(EDT!$K$7:$K$124,EDT!$J$7:$J$124,$A7,EDT!$M$7:$M$124,"<>Recortada") -> 77.5 | F7: =IFERROR(E7/D7,0) -> 3.875 | G7: =IF(E7>D7,"Sobrecarga","OK") -> Sobrecarga | H7: =SUMIFS(EDT!$K$7:$K$124,EDT!$J$7:$J$124,$A7,EDT!$E$7:$E$124,Listas!$A$2,EDT!$M$7:$M$124,"<>Recortada") -> 0 | I7: =SUMIFS(EDT!$K$7:$K$124,EDT!$J$7:$J$124,$A7,EDT!$E$7:$E$124,Listas!$A$3,EDT!$M$7:$M$124,"<>Recortada") -> 0 | J7: =E7-H7-I7 -> 77.5 | K7: =SUMIFS(EDT!$K$7:$K$124,EDT!$J$7:$J$124,$A7,EDT!$D$7:$D$124,Listas!$B$2,EDT!$M$7:$M$124,"<>Recortada") -> 41 | L7: =SUMIFS(EDT!$K$7:$K$124,EDT!$J$7:$J$124,$A7,EDT!$D$7:$D$124,Listas!$B$3,EDT!$M$7:$M$124,"<>Recortada") -> 32.5 | M7: =SUMIFS(EDT!$K$7:$K$124,EDT!$J$7:$J$124,$A7,EDT!$D$7:$D$124,Listas!$B$4,EDT!$M$7:$M$124,"<>Recortada") -> 4
A8: =Listas!F3 -> Jue 29 | B8: Informes (revisión y aprobación), vista del médico, mensual, evaluación, prueba en frío, tag m2-entrega y enlace en el aula virtual antes de la medianoche. | C8: 12 | D8: =C8*$C$3 -> 24 | E8: =SUMIFS(EDT!$K$7:$K$124,EDT!$J$7:$J$124,$A8,EDT!$M$7:$M$124,"<>Recortada") -> 101.5 | F8: =IFERROR(E8/D8,0) -> 4.2291667 | G8: =IF(E8>D8,"Sobrecarga","OK") -> Sobrecarga | H8: =SUMIFS(EDT!$K$7:$K$124,EDT!$J$7:$J$124,$A8,EDT!$E$7:$E$124,Listas!$A$2,EDT!$M$7:$M$124,"<>Recortada") -> 0 | I8: =SUMIFS(EDT!$K$7:$K$124,EDT!$J$7:$J$124,$A8,EDT!$E$7:$E$124,Listas!$A$3,EDT!$M$7:$M$124,"<>Recortada") -> 0 | J8: =E8-H8-I8 -> 101.5 | K8: =SUMIFS(EDT!$K$7:$K$124,EDT!$J$7:$J$124,$A8,EDT!$D$7:$D$124,Listas!$B$2,EDT!$M$7:$M$124,"<>Recortada") -> 49 | L8: =SUMIFS(EDT!$K$7:$K$124,EDT!$J$7:$J$124,$A8,EDT!$D$7:$D$124,Listas!$B$3,EDT!$M$7:$M$124,"<>Recortada") -> 27 | M8: =SUMIFS(EDT!$K$7:$K$124,EDT!$J$7:$J$124,$A8,EDT!$D$7:$D$124,Listas!$B$4,EDT!$M$7:$M$124,"<>Recortada") -> 25.5
A9: =Listas!F4 -> Vie 30 | B9: Congelado: ensayo de la demo de 6 minutos y respuestas sobre las decisiones. No se integra nada nuevo. | C9: 6 | D9: =C9*$C$3 -> 12 | E9: =SUMIFS(EDT!$K$7:$K$124,EDT!$J$7:$J$124,$A9,EDT!$M$7:$M$124,"<>Recortada") -> 4 | F9: =IFERROR(E9/D9,0) -> 0.33333333 | G9: =IF(E9>D9,"Sobrecarga","OK") -> OK | H9: =SUMIFS(EDT!$K$7:$K$124,EDT!$J$7:$J$124,$A9,EDT!$E$7:$E$124,Listas!$A$2,EDT!$M$7:$M$124,"<>Recortada") -> 0 | I9: =SUMIFS(EDT!$K$7:$K$124,EDT!$J$7:$J$124,$A9,EDT!$E$7:$E$124,Listas!$A$3,EDT!$M$7:$M$124,"<>Recortada") -> 0 | J9: =E9-H9-I9 -> 4 | K9: =SUMIFS(EDT!$K$7:$K$124,EDT!$J$7:$J$124,$A9,EDT!$D$7:$D$124,Listas!$B$2,EDT!$M$7:$M$124,"<>Recortada") -> 0 | L9: =SUMIFS(EDT!$K$7:$K$124,EDT!$J$7:$J$124,$A9,EDT!$D$7:$D$124,Listas!$B$3,EDT!$M$7:$M$124,"<>Recortada") -> 0 | M9: =SUMIFS(EDT!$K$7:$K$124,EDT!$J$7:$J$124,$A9,EDT!$D$7:$D$124,Listas!$B$4,EDT!$M$7:$M$124,"<>Recortada") -> 4
A10: =Listas!F5 -> Sáb 31 | B10: Demo en vivo: 6 minutos más 3 de preguntas. | C10: 4 | D10: =C10*$C$3 -> 8 | E10: =SUMIFS(EDT!$K$7:$K$124,EDT!$J$7:$J$124,$A10,EDT!$M$7:$M$124,"<>Recortada") -> 2 | F10: =IFERROR(E10/D10,0) -> 0.25 | G10: =IF(E10>D10,"Sobrecarga","OK") -> OK | H10: =SUMIFS(EDT!$K$7:$K$124,EDT!$J$7:$J$124,$A10,EDT!$E$7:$E$124,Listas!$A$2,EDT!$M$7:$M$124,"<>Recortada") -> 0 | I10: =SUMIFS(EDT!$K$7:$K$124,EDT!$J$7:$J$124,$A10,EDT!$E$7:$E$124,Listas!$A$3,EDT!$M$7:$M$124,"<>Recortada") -> 0 | J10: =E10-H10-I10 -> 2 | K10: =SUMIFS(EDT!$K$7:$K$124,EDT!$J$7:$J$124,$A10,EDT!$D$7:$D$124,Listas!$B$2,EDT!$M$7:$M$124,"<>Recortada") -> 0 | L10: =SUMIFS(EDT!$K$7:$K$124,EDT!$J$7:$J$124,$A10,EDT!$D$7:$D$124,Listas!$B$3,EDT!$M$7:$M$124,"<>Recortada") -> 0 | M10: =SUMIFS(EDT!$K$7:$K$124,EDT!$J$7:$J$124,$A10,EDT!$D$7:$D$124,Listas!$B$4,EDT!$M$7:$M$124,"<>Recortada") -> 2
A11: Total Mié a Sáb | D11: =SUM(D7:D10) -> 64 | E11: =SUM(E7:E10) -> 185 | F11: =IFERROR(E11/D11,0) -> 2.890625 | G11: =IF(E11>D11,"Sobrecarga","OK") -> Sobrecarga | H11: =SUM(H7:H10) -> 0 | I11: =SUM(I7:I10) -> 0 | J11: =SUM(J7:J10) -> 185 | K11: =SUM(K7:K10) -> 90 | L11: =SUM(L7:L10) -> 59.5 | M11: =SUM(M7:M10) -> 35.5
A12: Horas de sobrecarga (suma de los días que se pasan de su capacidad) | E12: =SUMPRODUCT((E7:E10>D7:D10)*(E7:E10-D7:D10)) -> 135
A14: 2 · Qué cabe antes de la medianoche del jueves (tareas planeadas para Mié y Jue)
A15: Prioridad | B15: Qué incluye | C15: Horas | D15: Acumulado (h) | E15: Capacidad Mié+Jue (h) | F15: Resultado | G15: Margen (h)
A16: =Listas!D2 -> 1 · Imprescindible | B16: Puerta de aceptación y causas de anulación: app que levanta sola, agente con sus límites, trazas y cifras, aprobación por enfermería, entrega. | C16: =SUMIFS(EDT!$K$7:$K$124,EDT!$H$7:$H$124,$A16,EDT!$J$7:$J$124,$A$7,EDT!$M$7:$M$124,"<>Recortada")+SUMIFS(EDT!$K$7:$K$124,EDT!$H$7:$H$124,$A16,EDT!$J$7:$J$124,$A$8,EDT!$M$7:$M$124,"<>Recortada") -> 115 | D16: =SUM($C$16:C16) -> 115 | E16: =$D$7+$D$8 -> 44 | F16: =IF(D16<=E16,"Cabe","No cabe") -> No cabe | G16: =E16-D16 -> -71
A17: =Listas!D3 -> 2 · Núcleo | B17: El resto del núcleo de M2 (M2-N). | C17: =SUMIFS(EDT!$K$7:$K$124,EDT!$H$7:$H$124,$A17,EDT!$J$7:$J$124,$A$7,EDT!$M$7:$M$124,"<>Recortada")+SUMIFS(EDT!$K$7:$K$124,EDT!$H$7:$H$124,$A17,EDT!$J$7:$J$124,$A$8,EDT!$M$7:$M$124,"<>Recortada") -> 44.5 | D17: =SUM($C$16:C17) -> 159.5 | E17: =$D$7+$D$8 -> 44 | F17: =IF(D17<=E17,"Cabe","No cabe") -> No cabe | G17: =E17-D17 -> -115.5
A18: =Listas!D4 -> 3 · Si hay tiempo | B18: «Si hay tiempo» (M2-S): es lo primero que se recorta. | C18: =SUMIFS(EDT!$K$7:$K$124,EDT!$H$7:$H$124,$A18,EDT!$J$7:$J$124,$A$7,EDT!$M$7:$M$124,"<>Recortada")+SUMIFS(EDT!$K$7:$K$124,EDT!$H$7:$H$124,$A18,EDT!$J$7:$J$124,$A$8,EDT!$M$7:$M$124,"<>Recortada") -> 13 | D18: =SUM($C$16:C18) -> 172.5 | E18: =$D$7+$D$8 -> 44 | F18: =IF(D18<=E18,"Cabe","No cabe") -> No cabe | G18: =E18-D18 -> -128.5
A19: =Listas!D5 -> 4 · Opcional | B19: Opcionales (PDF y voz): solo con todo lo demás cerrado. | C19: =SUMIFS(EDT!$K$7:$K$124,EDT!$H$7:$H$124,$A19,EDT!$J$7:$J$124,$A$7,EDT!$M$7:$M$124,"<>Recortada")+SUMIFS(EDT!$K$7:$K$124,EDT!$H$7:$H$124,$A19,EDT!$J$7:$J$124,$A$8,EDT!$M$7:$M$124,"<>Recortada") -> 6.5 | D19: =SUM($C$16:C19) -> 179 | E19: =$D$7+$D$8 -> 44 | F19: =IF(D19<=E19,"Cabe","No cabe") -> No cabe | G19: =E19-D19 -> -135
A20: Cómo leerlo: «Cabe» quiere decir que todo lo de esa prioridad y de las anteriores, planeado para Mié y Jue, entra en la capacidad del equipo de esos dos días. Donde aparezca el primer «No cabe» hay que recortar (Estado = Recortada en la hoja EDT) o revisar las horas estimadas con las «Horas reales».
A22: 3 · Tareas por día
A23: ID | B23: Tarea | C23: Responsable | D23: Prioridad | E23: =Listas!F2 -> Mié 28 | F23: =Listas!F3 -> Jue 29 | G23: =Listas!F4 -> Vie 30 | H23: =Listas!F5 -> Sáb 31 | I23: Estado
A24: =EDT!A8 -> 1.1 | B24: =EDT!B8 -> Quitar la exigencia de JWT_SECRET en el Momento 2 | C24: =IF(EDT!E8="","",EDT!E8) | D24: =EDT!H8 -> 1 · Imprescindible | E24: =IF(AND(EDT!$J8=E$23,EDT!$M8<>"Recortada"),EDT!$K8,"") -> 1 | F24: =IF(AND(EDT!$J8=F$23,EDT!$M8<>"Recortada"),EDT!$K8,"") | G24: =IF(AND(EDT!$J8=G$23,EDT!$M8<>"Recortada"),EDT!$K8,"") | H24: =IF(AND(EDT!$J8=H$23,EDT!$M8<>"Recortada"),EDT!$K8,"") | I24: =EDT!M8 -> Pendiente
A25: =EDT!A9 -> 1.2 | B25: =EDT!B9 -> Dockerfile del backend con CMD | C25: =IF(EDT!E9="","",EDT!E9) | D25: =EDT!H9 -> 1 · Imprescindible | E25: =IF(AND(EDT!$J9=E$23,EDT!$M9<>"Recortada"),EDT!$K9,"") -> 1 | F25: =IF(AND(EDT!$J9=F$23,EDT!$M9<>"Recortada"),EDT!$K9,"") | G25: =IF(AND(EDT!$J9=G$23,EDT!$M9<>"Recortada"),EDT!$K9,"") | H25: =IF(AND(EDT!$J9=H$23,EDT!$M9<>"Recortada"),EDT!$K9,"") | I25: =EDT!M9 -> Pendiente
A26: =EDT!A10 -> 1.3 | B26: =EDT!B10 -> Dockerfile del frontend multi-etapa | C26: =IF(EDT!E10="","",EDT!E10) | D26: =EDT!H10 -> 1 · Imprescindible | E26: =IF(AND(EDT!$J10=E$23,EDT!$M10<>"Recortada"),EDT!$K10,"") -> 1.5 | F26: =IF(AND(EDT!$J10=F$23,EDT!$M10<>"Recortada"),EDT!$K10,"") | G26: =IF(AND(EDT!$J10=G$23,EDT!$M10<>"Recortada"),EDT!$K10,"") | H26: =IF(AND(EDT!$J10=H$23,EDT!$M10<>"Recortada"),EDT!$K10,"") | I26: =EDT!M10 -> Pendiente
A27: =EDT!A11 -> 1.4 | B27: =EDT!B11 -> docker-compose.yml | C27: =IF(EDT!E11="","",EDT!E11) | D27: =EDT!H11 -> 1 · Imprescindible | E27: =IF(AND(EDT!$J11=E$23,EDT!$M11<>"Recortada"),EDT!$K11,"") -> 2 | F27: =IF(AND(EDT!$J11=F$23,EDT!$M11<>"Recortada"),EDT!$K11,"") | G27: =IF(AND(EDT!$J11=G$23,EDT!$M11<>"Recortada"),EDT!$K11,"") | H27: =IF(AND(EDT!$J11=H$23,EDT!$M11<>"Recortada"),EDT!$K11,"") | I27: =EDT!M11 -> Pendiente
A28: =EDT!A12 -> 1.5 | B28: =EDT!B12 -> .env.example | C28: =IF(EDT!E12="","",EDT!E12) | D28: =EDT!H12 -> 1 · Imprescindible | E28: =IF(AND(EDT!$J12=E$23,EDT!$M12<>"Recortada"),EDT!$K12,"") -> 0.5 | F28: =IF(AND(EDT!$J12=F$23,EDT!$M12<>"Recortada"),EDT!$K12,"") | G28: =IF(AND(EDT!$J12=G$23,EDT!$M12<>"Recortada"),EDT!$K12,"") | H28: =IF(AND(EDT!$J12=H$23,EDT!$M12<>"Recortada"),EDT!$K12,"") | I28: =EDT!M12 -> Pendiente
A29: =EDT!A13 -> 1.6 | B29: =EDT!B13 -> run.sh | C29: =IF(EDT!E13="","",EDT!E13) | D29: =EDT!H13 -> 1 · Imprescindible | E29: =IF(AND(EDT!$J13=E$23,EDT!$M13<>"Recortada"),EDT!$K13,"") -> 2 | F29: =IF(AND(EDT!$J13=F$23,EDT!$M13<>"Recortada"),EDT!$K13,"") | G29: =IF(AND(EDT!$J13=G$23,EDT!$M13<>"Recortada"),EDT!$K13,"") | H29: =IF(AND(EDT!$J13=H$23,EDT!$M13<>"Recortada"),EDT!$K13,"") | I29: =EDT!M13 -> Pendiente
A30: =EDT!A14 -> 1.7 | B30: =EDT!B14 -> Aviso de llave faltante en la app | C30: =IF(EDT!E14="","",EDT!E14) | D30: =EDT!H14 -> 1 · Imprescindible | E30: =IF(AND(EDT!$J14=E$23,EDT!$M14<>"Recortada"),EDT!$K14,"") | F30: =IF(AND(EDT!$J14=F$23,EDT!$M14<>"Recortada"),EDT!$K14,"") -> 1.5 | G30: =IF(AND(EDT!$J14=G$23,EDT!$M14<>"Recortada"),EDT!$K14,"") | H30: =IF(AND(EDT!$J14=H$23,EDT!$M14<>"Recortada"),EDT!$K14,"") | I30: =EDT!M14 -> Pendiente
A31: =EDT!A16 -> 2.1 | B31: =EDT!B16 -> V3: tablas de usuarios y entradas | C31: =IF(EDT!E16="","",EDT!E16) | D31: =EDT!H16 -> 1 · Imprescindible | E31: =IF(AND(EDT!$J16=E$23,EDT!$M16<>"Recortada"),EDT!$K16,"") -> 1.5 | F31: =IF(AND(EDT!$J16=F$23,EDT!$M16<>"Recortada"),EDT!$K16,"") | G31: =IF(AND(EDT!$J16=G$23,EDT!$M16<>"Recortada"),EDT!$K16,"") | H31: =IF(AND(EDT!$J16=H$23,EDT!$M16<>"Recortada"),EDT!$K16,"") | I31: =EDT!M16 -> Pendiente
A32: =EDT!A17 -> 2.2 | B32: =EDT!B17 -> V3: tablas de informes | C32: =IF(EDT!E17="","",EDT!E17) | D32: =EDT!H17 -> 1 · Imprescindible | E32: =IF(AND(EDT!$J17=E$23,EDT!$M17<>"Recortada"),EDT!$K17,"") -> 1.5 | F32: =IF(AND(EDT!$J17=F$23,EDT!$M17<>"Recortada"),EDT!$K17,"") | G32: =IF(AND(EDT!$J17=G$23,EDT!$M17<>"Recortada"),EDT!$K17,"") | H32: =IF(AND(EDT!$J17=H$23,EDT!$M17<>"Recortada"),EDT!$K17,"") | I32: =EDT!M17 -> Pendiente
A33: =EDT!A18 -> 2.3 | B33: =EDT!B18 -> V3: tablas del agente | C33: =IF(EDT!E18="","",EDT!E18) | D33: =EDT!H18 -> 1 · Imprescindible | E33: =IF(AND(EDT!$J18=E$23,EDT!$M18<>"Recortada"),EDT!$K18,"") -> 1 | F33: =IF(AND(EDT!$J18=F$23,EDT!$M18<>"Recortada"),EDT!$K18,"") | G33: =IF(AND(EDT!$J18=G$23,EDT!$M18<>"Recortada"),EDT!$K18,"") | H33: =IF(AND(EDT!$J18=H$23,EDT!$M18<>"Recortada"),EDT!$K18,"") | I33: =EDT!M18 -> Pendiente
A34: =EDT!A19 -> 2.4 | B34: =EDT!B19 -> V3: tablas de «si hay tiempo» | C34: =IF(EDT!E19="","",EDT!E19) | D34: =EDT!H19 -> 3 · Si hay tiempo | E34: =IF(AND(EDT!$J19=E$23,EDT!$M19<>"Recortada"),EDT!$K19,"") | F34: =IF(AND(EDT!$J19=F$23,EDT!$M19<>"Recortada"),EDT!$K19,"") -> 1 | G34: =IF(AND(EDT!$J19=G$23,EDT!$M19<>"Recortada"),EDT!$K19,"") | H34: =IF(AND(EDT!$J19=H$23,EDT!$M19<>"Recortada"),EDT!$K19,"") | I34: =EDT!M19 -> Pendiente
A35: =EDT!A20 -> 2.5 | B35: =EDT!B20 -> V4: roles y permisos del dominio | C35: =IF(EDT!E20="","",EDT!E20) | D35: =EDT!H20 -> 1 · Imprescindible | E35: =IF(AND(EDT!$J20=E$23,EDT!$M20<>"Recortada"),EDT!$K20,"") -> 1.5 | F35: =IF(AND(EDT!$J20=F$23,EDT!$M20<>"Recortada"),EDT!$K20,"") | G35: =IF(AND(EDT!$J20=G$23,EDT!$M20<>"Recortada"),EDT!$K20,"") | H35: =IF(AND(EDT!$J20=H$23,EDT!$M20<>"Recortada"),EDT!$K20,"") | I35: =EDT!M20 -> Pendiente
A36: =EDT!A21 -> 2.6 | B36: =EDT!B21 -> Entidades y repositorios | C36: =IF(EDT!E21="","",EDT!E21) | D36: =EDT!H21 -> 1 · Imprescindible | E36: =IF(AND(EDT!$J21=E$23,EDT!$M21<>"Recortada"),EDT!$K21,"") -> 2 | F36: =IF(AND(EDT!$J21=F$23,EDT!$M21<>"Recortada"),EDT!$K21,"") | G36: =IF(AND(EDT!$J21=G$23,EDT!$M21<>"Recortada"),EDT!$K21,"") | H36: =IF(AND(EDT!$J21=H$23,EDT!$M21<>"Recortada"),EDT!$K21,"") | I36: =EDT!M21 -> Pendiente
A37: =EDT!A22 -> 2.7 | B37: =EDT!B22 -> Semilla: usuarios de demostración | C37: =IF(EDT!E22="","",EDT!E22) | D37: =EDT!H22 -> 1 · Imprescindible | E37: =IF(AND(EDT!$J22=E$23,EDT!$M22<>"Recortada"),EDT!$K22,"") -> 2 | F37: =IF(AND(EDT!$J22=F$23,EDT!$M22<>"Recortada"),EDT!$K22,"") | G37: =IF(AND(EDT!$J22=G$23,EDT!$M22<>"Recortada"),EDT!$K22,"") | H37: =IF(AND(EDT!$J22=H$23,EDT!$M22<>"Recortada"),EDT!$K22,"") | I37: =EDT!M22 -> Pendiente
A38: =EDT!A23 -> 2.8 | B38: =EDT!B23 -> Datos del paciente 1 | C38: =IF(EDT!E23="","",EDT!E23) | D38: =EDT!H23 -> 1 · Imprescindible | E38: =IF(AND(EDT!$J23=E$23,EDT!$M23<>"Recortada"),EDT!$K23,"") -> 2.5 | F38: =IF(AND(EDT!$J23=F$23,EDT!$M23<>"Recortada"),EDT!$K23,"") | G38: =IF(AND(EDT!$J23=G$23,EDT!$M23<>"Recortada"),EDT!$K23,"") | H38: =IF(AND(EDT!$J23=H$23,EDT!$M23<>"Recortada"),EDT!$K23,"") | I38: =EDT!M23 -> Pendiente
A39: =EDT!A24 -> 2.9 | B39: =EDT!B24 -> Datos del paciente 2 | C39: =IF(EDT!E24="","",EDT!E24) | D39: =EDT!H24 -> 2 · Núcleo | E39: =IF(AND(EDT!$J24=E$23,EDT!$M24<>"Recortada"),EDT!$K24,"") | F39: =IF(AND(EDT!$J24=F$23,EDT!$M24<>"Recortada"),EDT!$K24,"") -> 2 | G39: =IF(AND(EDT!$J24=G$23,EDT!$M24<>"Recortada"),EDT!$K24,"") | H39: =IF(AND(EDT!$J24=H$23,EDT!$M24<>"Recortada"),EDT!$K24,"") | I39: =EDT!M24 -> Pendiente
A40: =EDT!A25 -> 2.10 | B40: =EDT!B25 -> Datos del paciente 3 | C40: =IF(EDT!E25="","",EDT!E25) | D40: =EDT!H25 -> 2 · Núcleo | E40: =IF(AND(EDT!$J25=E$23,EDT!$M25<>"Recortada"),EDT!$K25,"") | F40: =IF(AND(EDT!$J25=F$23,EDT!$M25<>"Recortada"),EDT!$K25,"") -> 1.5 | G40: =IF(AND(EDT!$J25=G$23,EDT!$M25<>"Recortada"),EDT!$K25,"") | H40: =IF(AND(EDT!$J25=H$23,EDT!$M25<>"Recortada"),EDT!$K25,"") | I40: =EDT!M25 -> Pendiente
A41: =EDT!A26 -> 2.11 | B41: =EDT!B26 -> Datos del paciente 4 | C41: =IF(EDT!E26="","",EDT!E26) | D41: =EDT!H26 -> 2 · Núcleo | E41: =IF(AND(EDT!$J26=E$23,EDT!$M26<>"Recortada"),EDT!$K26,"") | F41: =IF(AND(EDT!$J26=F$23,EDT!$M26<>"Recortada"),EDT!$K26,"") -> 1.5 | G41: =IF(AND(EDT!$J26=G$23,EDT!$M26<>"Recortada"),EDT!$K26,"") | H41: =IF(AND(EDT!$J26=H$23,EDT!$M26<>"Recortada"),EDT!$K26,"") | I41: =EDT!M26 -> Pendiente
A42: =EDT!A27 -> 2.12 | B42: =EDT!B27 -> Datos del paciente 5 | C42: =IF(EDT!E27="","",EDT!E27) | D42: =EDT!H27 -> 2 · Núcleo | E42: =IF(AND(EDT!$J27=E$23,EDT!$M27<>"Recortada"),EDT!$K27,"") | F42: =IF(AND(EDT!$J27=F$23,EDT!$M27<>"Recortada"),EDT!$K27,"") -> 1 | G42: =IF(AND(EDT!$J27=G$23,EDT!$M27<>"Recortada"),EDT!$K27,"") | H42: =IF(AND(EDT!$J27=H$23,EDT!$M27<>"Recortada"),EDT!$K27,"") | I42: =EDT!M27 -> Pendiente
... A44: =EDT!A29 -> 2.14 | B44: =EDT!B29 -> Prueba de idempotencia de la semilla | C44: =IF(EDT!E29="","",EDT!E29) | D44: =EDT!H29 -> 1 · Imprescindible | E44: =IF(AND(EDT!$J29=E$23,EDT!$M29<>"Recortada"),EDT!$K29,"") | F44: =IF(AND(EDT!$J29=F$23,EDT!$M29<>"Recortada"),EDT!$K29,"") -> 0.5 | G44: =IF(AND(EDT!$J29=G$23,EDT!$M29<>"Recortada"),EDT!$K29,"") | H44: =IF(AND(EDT!$J29=H$23,EDT!$M29<>"Recortada"),EDT!$K29,"") | I44: =EDT!M29 -> Pendiente
...

Sheet Listas
A1: Responsable | B1: Frente | C1: Hito | D1: Prioridad | E1: Estado | F1: Día
A2: Breiner | B2: A · Plataforma y datos | C2: M2-N | D2: 1 · Imprescindible | E2: Pendiente | F2: Mié 28
A3: Andres | B3: B · Agente e informe | C3: M2-S | D3: 2 · Núcleo | E3: En curso | F3: Jue 29
B4: AB · Compartida | C4: Opc | D4: 3 · Si hay tiempo | E4: Bloqueada | F4: Vie 30
D5: 4 · Opcional | E5: Hecha | F5: Sáb 31
E6: Recortada
A9: Estas listas alimentan los desplegables de la hoja EDT y los encabezados del Cronograma.
A10: Si cambia un nombre aquí (por ejemplo un día), cámbielo también en la hoja EDT con Buscar y reemplazar.
A11: El equipo son dos personas; el Cronograma muestra una columna por cada una de las dos primeras filas de «Responsable».
